<mujoco>
    <default>
        <joint type="hinge" frictionloss="0.1" damping='2' />
        <position ctrllimited="true" ctrlrange="-3.14 3.14" forcelimited="true" forcerange="-50 50" kp="10" />
    </default>

    <asset>
        <texture type="skybox" builtin="gradient" rgb1="0.3 0.5 0.7" rgb2="0 0 0" width="512" height="512" />
        <texture name="texplane" type="2d" builtin="checker" rgb1=".2 .3 .4" rgb2=".1 0.15 0.2" width="512" height="512" mark="cross" markrgb=".8 .8 .8" />

        <material name="matplane" reflectance="0.3" texture="texplane" texrepeat="1 1" texuniform="true" />
    </asset>

    <worldbody>
        <light directional="true" diffuse=".4 .4 .4" specular="0.1 0.1 0.1" pos="0 0 5.0" dir="0 0 -1" castshadow="false" />
        <light directional="true" diffuse=".6 .6 .6" specular="0.2 0.2 0.2" pos="0 0 4" dir="0 0 -1" />

        <geom name="ground" type="plane" size="0 0 1" pos="0 0 0" quat="1 0 0 0" material="matplane" condim="1" />

        <body name="b0" pos="0 0 1">
            <geom type="box" size="0.2 0.025 0.025" rgba=".8 .2 .1 1" />
            <body name="b1" pos="-0.2 0 -0.2" euler="0 90 0">
                <geom type="box" size="0.2 0.025 0.025" rgba=".8 .2 .1 1" />
                <joint name="j0" type="hinge" pos="-0.2 0 0" axis="0 1 0" />
                <body name="b4" pos="0.2 0 0.05" euler="0 90 0">
                    <geom type="box" size="0.05 0.025 0.025" rgba="1 1 0 1" />
                    <joint name="j4" type="hinge" pos="0.05 0 0" axis="0 1 0" />
                </body>
            </body>
            <body name="b2" pos="0.2 0 -0.2" euler="0 90 0">
                <geom type="box" size="0.2 0.025 0.025" rgba=".8 .2 .1 1" />
                <joint name="j2" type="hinge" pos="-0.2 0 0" axis="0 1 0" />
                <body name="b5" pos="0.2 0 -0.05" euler="0 90 0">
                    <geom type="box" size="0.05 0.025 0.025" rgba="1 1 0 1" />
                    <joint name="j5" type="hinge" pos="-0.05 0 0" axis="0 1 0" />
                </body>
            </body>
        </body>

        <body name="b3" pos="0 0 0.6" euler="0 0 0">
            <freejoint />
            <geom type="box" size="0.1 0.025 0.025" rgba=".8 .2 .1 1" />
        </body>
    </worldbody>

    <contact>
        <exclude name="e0" body1="b0" body2="b1" />
        <exclude name="e1" body1="b0" body2="b2" />
        <exclude name="e2" body1="b3" body2="b4" />
        <exclude name="e3" body1="b3" body2="b5" />
        <exclude name="e4" body1="b1" body2="b4" />
        <exclude name="e5" body1="b2" body2="b5" />
    </contact>

    <equality>
        <connect name="c1" body1="b4" body2="b3" anchor="0.2 0 0" />
        <connect name="c2" body1="b4" body2="b3" anchor="0.2 0 0" />
        <connect name="c3" body1="b4" body2="b3" anchor="0.2 0 0" />
    </equality>

    <actuator>
        <position joint="j0" ctrllimited="true" ctrlrange="-0.875 0.875" />
        <position joint="j2" ctrllimited="true" ctrlrange="-0.875 0.875" />
        <position joint="j4" ctrllimited="true" ctrlrange="-0.875 0.875" />
        <position joint="j5" ctrllimited="true" ctrlrange="-0.875 0.875" />
    </actuator>
</mujoco>